<?xml version="1.0"?>
<robot name="g1_29dof_simple">
  <material name="dark">
    <color rgba="0.08 0.08 0.08 1"/>
  </material>
  <material name="gray">
    <color rgba="0.45 0.45 0.45 1"/>
  </material>
  <material name="blue">
    <color rgba="0.1 0.35 0.9 1"/>
  </material>

  <link name="world"/>

  <link name="pelvis">
    <visual>
      <geometry>
        <box size="0.28 0.22 0.18"/>
      </geometry>
      <material name="gray"/>
    </visual>
  </link>

  <joint name="floating_base_joint" type="fixed">
    <origin xyz="0 0 0.85" rpy="0 0 0"/>
    <parent link="world"/>
    <child link="pelvis"/>
  </joint>

  <link name="waist_yaw_link">
    <visual>
      <geometry>
        <cylinder radius="0.10" length="0.08"/>
      </geometry>
      <material name="dark"/>
    </visual>
  </link>
  <joint name="waist_yaw_joint" type="revolute">
    <origin xyz="0 0 0.11" rpy="0 0 0"/>
    <parent link="pelvis"/>
    <child link="waist_yaw_link"/>
    <axis xyz="0 0 1"/>
    <limit lower="-1.57" upper="1.57" effort="80" velocity="8"/>
  </joint>

  <link name="waist_roll_link">
    <visual>
      <geometry>
        <box size="0.18 0.16 0.08"/>
      </geometry>
      <material name="dark"/>
    </visual>
  </link>
  <joint name="waist_roll_joint" type="revolute">
    <origin xyz="0 0 0.06" rpy="0 0 0"/>
    <parent link="waist_yaw_link"/>
    <child link="waist_roll_link"/>
    <axis xyz="1 0 0"/>
    <limit lower="-0.8" upper="0.8" effort="80" velocity="8"/>
  </joint>

  <link name="torso_link">
    <visual>
      <origin xyz="0 0 0.18" rpy="0 0 0"/>
      <geometry>
        <box size="0.34 0.24 0.36"/>
      </geometry>
      <material name="gray"/>
    </visual>
  </link>
  <joint name="waist_pitch_joint" type="revolute">
    <origin xyz="0 0 0.06" rpy="0 0 0"/>
    <parent link="waist_roll_link"/>
    <child link="torso_link"/>
    <axis xyz="0 1 0"/>
    <limit lower="-0.8" upper="0.8" effort="80" velocity="8"/>
  </joint>

  <link name="head_link">
    <visual>
      <origin xyz="0 0 0.08" rpy="0 0 0"/>
      <geometry>
        <box size="0.20 0.18 0.16"/>
      </geometry>
      <material name="dark"/>
    </visual>
  </link>
  <joint name="head_joint" type="fixed">
    <origin xyz="0 0 0.40" rpy="0 0 0"/>
    <parent link="torso_link"/>
    <child link="head_link"/>
  </joint>

  <link name="left_hip_pitch_link"/>
  <joint name="left_hip_pitch_joint" type="revolute">
    <origin xyz="0 0.09 -0.10" rpy="0 0 0"/>
    <parent link="pelvis"/>
    <child link="left_hip_pitch_link"/>
    <axis xyz="0 1 0"/>
    <limit lower="-2.5" upper="2.5" effort="100" velocity="10"/>
  </joint>
  <link name="left_hip_roll_link"/>
  <joint name="left_hip_roll_joint" type="revolute">
    <parent link="left_hip_pitch_link"/>
    <child link="left_hip_roll_link"/>
    <axis xyz="1 0 0"/>
    <limit lower="-1.57" upper="1.57" effort="100" velocity="10"/>
  </joint>
  <link name="left_hip_yaw_link"/>
  <joint name="left_hip_yaw_joint" type="revolute">
    <parent link="left_hip_roll_link"/>
    <child link="left_hip_yaw_link"/>
    <axis xyz="0 0 1"/>
    <limit lower="-1.57" upper="1.57" effort="100" velocity="10"/>
  </joint>
  <link name="left_thigh_link">
    <visual>
      <origin xyz="0 0 -0.18" rpy="0 0 0"/>
      <geometry>
        <box size="0.09 0.09 0.36"/>
      </geometry>
      <material name="blue"/>
    </visual>
  </link>
  <joint name="left_knee_joint" type="revolute">
    <origin xyz="0 0 -0.36" rpy="0 0 0"/>
    <parent link="left_hip_yaw_link"/>
    <child link="left_thigh_link"/>
    <axis xyz="0 1 0"/>
    <limit lower="-0.2" upper="2.6" effort="100" velocity="10"/>
  </joint>
  <link name="left_ankle_pitch_link">
    <visual>
      <origin xyz="0 0 -0.16" rpy="0 0 0"/>
      <geometry>
        <box size="0.08 0.08 0.32"/>
      </geometry>
      <material name="gray"/>
    </visual>
  </link>
  <joint name="left_ankle_pitch_joint" type="revolute">
    <origin xyz="0 0 -0.36" rpy="0 0 0"/>
    <parent link="left_thigh_link"/>
    <child link="left_ankle_pitch_link"/>
    <axis xyz="0 1 0"/>
    <limit lower="-1.2" upper="1.2" effort="80" velocity="10"/>
  </joint>
  <link name="left_foot_link">
    <visual>
      <origin xyz="0.06 0 -0.03" rpy="0 0 0"/>
      <geometry>
        <box size="0.24 0.10 0.06"/>
      </geometry>
      <material name="dark"/>
    </visual>
  </link>
  <joint name="left_ankle_roll_joint" type="revolute">
    <origin xyz="0 0 -0.32" rpy="0 0 0"/>
    <parent link="left_ankle_pitch_link"/>
    <child link="left_foot_link"/>
    <axis xyz="1 0 0"/>
    <limit lower="-0.8" upper="0.8" effort="80" velocity="10"/>
  </joint>

  <link name="right_hip_pitch_link"/>
  <joint name="right_hip_pitch_joint" type="revolute">
    <origin xyz="0 -0.09 -0.10" rpy="0 0 0"/>
    <parent link="pelvis"/>
    <child link="right_hip_pitch_link"/>
    <axis xyz="0 1 0"/>
    <limit lower="-2.5" upper="2.5" effort="100" velocity="10"/>
  </joint>
  <link name="right_hip_roll_link"/>
  <joint name="right_hip_roll_joint" type="revolute">
    <parent link="right_hip_pitch_link"/>
    <child link="right_hip_roll_link"/>
    <axis xyz="1 0 0"/>
    <limit lower="-1.57" upper="1.57" effort="100" velocity="10"/>
  </joint>
  <link name="right_hip_yaw_link"/>
  <joint name="right_hip_yaw_joint" type="revolute">
    <parent link="right_hip_roll_link"/>
    <child link="right_hip_yaw_link"/>
    <axis xyz="0 0 1"/>
    <limit lower="-1.57" upper="1.57" effort="100" velocity="10"/>
  </joint>
  <link name="right_thigh_link">
    <visual>
      <origin xyz="0 0 -0.18" rpy="0 0 0"/>
      <geometry>
        <box size="0.09 0.09 0.36"/>
      </geometry>
      <material name="blue"/>
    </visual>
  </link>
  <joint name="right_knee_joint" type="revolute">
    <origin xyz="0 0 -0.36" rpy="0 0 0"/>
    <parent link="right_hip_yaw_link"/>
    <child link="right_thigh_link"/>
    <axis xyz="0 1 0"/>
    <limit lower="-0.2" upper="2.6" effort="100" velocity="10"/>
  </joint>
  <link name="right_ankle_pitch_link">
    <visual>
      <origin xyz="0 0 -0.16" rpy="0 0 0"/>
      <geometry>
        <box size="0.08 0.08 0.32"/>
      </geometry>
      <material name="gray"/>
    </visual>
  </link>
  <joint name="right_ankle_pitch_joint" type="revolute">
    <origin xyz="0 0 -0.36" rpy="0 0 0"/>
    <parent link="right_thigh_link"/>
    <child link="right_ankle_pitch_link"/>
    <axis xyz="0 1 0"/>
    <limit lower="-1.2" upper="1.2" effort="80" velocity="10"/>
  </joint>
  <link name="right_foot_link">
    <visual>
      <origin xyz="0.06 0 -0.03" rpy="0 0 0"/>
      <geometry>
        <box size="0.24 0.10 0.06"/>
      </geometry>
      <material name="dark"/>
    </visual>
  </link>
  <joint name="right_ankle_roll_joint" type="revolute">
    <origin xyz="0 0 -0.32" rpy="0 0 0"/>
    <parent link="right_ankle_pitch_link"/>
    <child link="right_foot_link"/>
    <axis xyz="1 0 0"/>
    <limit lower="-0.8" upper="0.8" effort="80" velocity="10"/>
  </joint>

  <link name="left_shoulder_pitch_link"/>
  <joint name="left_shoulder_pitch_joint" type="revolute">
    <origin xyz="0 0.18 0.30" rpy="0 0 0"/>
    <parent link="torso_link"/>
    <child link="left_shoulder_pitch_link"/>
    <axis xyz="0 1 0"/>
    <limit lower="-3.0" upper="3.0" effort="60" velocity="10"/>
  </joint>
  <link name="left_shoulder_roll_link"/>
  <joint name="left_shoulder_roll_joint" type="revolute">
    <parent link="left_shoulder_pitch_link"/>
    <child link="left_shoulder_roll_link"/>
    <axis xyz="1 0 0"/>
    <limit lower="-3.0" upper="3.0" effort="60" velocity="10"/>
  </joint>
  <link name="left_upper_arm_link">
    <visual>
      <origin xyz="0 0.14 0" rpy="0 0 0"/>
      <geometry>
        <box size="0.07 0.28 0.07"/>
      </geometry>
      <material name="blue"/>
    </visual>
  </link>
  <joint name="left_shoulder_yaw_joint" type="revolute">
    <parent link="left_shoulder_roll_link"/>
    <child link="left_upper_arm_link"/>
    <axis xyz="0 0 1"/>
    <limit lower="-3.0" upper="3.0" effort="60" velocity="10"/>
  </joint>
  <link name="left_elbow_link">
    <visual>
      <origin xyz="0 0.13 0" rpy="0 0 0"/>
      <geometry>
        <box size="0.06 0.26 0.06"/>
      </geometry>
      <material name="gray"/>
    </visual>
  </link>
  <joint name="left_elbow_joint" type="revolute">
    <origin xyz="0 0.28 0" rpy="0 0 0"/>
    <parent link="left_upper_arm_link"/>
    <child link="left_elbow_link"/>
    <axis xyz="0 1 0"/>
    <limit lower="-2.5" upper="2.5" effort="60" velocity="10"/>
  </joint>
  <link name="left_wrist_roll_link"/>
  <joint name="left_wrist_roll_joint" type="revolute">
    <origin xyz="0 0.26 0" rpy="0 0 0"/>
    <parent link="left_elbow_link"/>
    <child link="left_wrist_roll_link"/>
    <axis xyz="1 0 0"/>
    <limit lower="-3.0" upper="3.0" effort="30" velocity="10"/>
  </joint>
  <link name="left_wrist_pitch_link"/>
  <joint name="left_wrist_pitch_joint" type="revolute">
    <parent link="left_wrist_roll_link"/>
    <child link="left_wrist_pitch_link"/>
    <axis xyz="0 1 0"/>
    <limit lower="-2.0" upper="2.0" effort="30" velocity="10"/>
  </joint>
  <link name="left_hand_link">
    <visual>
      <origin xyz="0 0.06 0" rpy="0 0 0"/>
      <geometry>
        <box size="0.08 0.12 0.04"/>
      </geometry>
      <material name="dark"/>
    </visual>
  </link>
  <joint name="left_wrist_yaw_joint" type="revolute">
    <parent link="left_wrist_pitch_link"/>
    <child link="left_hand_link"/>
    <axis xyz="0 0 1"/>
    <limit lower="-3.0" upper="3.0" effort="30" velocity="10"/>
  </joint>

  <link name="right_shoulder_pitch_link"/>
  <joint name="right_shoulder_pitch_joint" type="revolute">
    <origin xyz="0 -0.18 0.30" rpy="0 0 0"/>
    <parent link="torso_link"/>
    <child link="right_shoulder_pitch_link"/>
    <axis xyz="0 1 0"/>
    <limit lower="-3.0" upper="3.0" effort="60" velocity="10"/>
  </joint>
  <link name="right_shoulder_roll_link"/>
  <joint name="right_shoulder_roll_joint" type="revolute">
    <parent link="right_shoulder_pitch_link"/>
    <child link="right_shoulder_roll_link"/>
    <axis xyz="1 0 0"/>
    <limit lower="-3.0" upper="3.0" effort="60" velocity="10"/>
  </joint>
  <link name="right_upper_arm_link">
    <visual>
      <origin xyz="0 -0.14 0" rpy="0 0 0"/>
      <geometry>
        <box size="0.07 0.28 0.07"/>
      </geometry>
      <material name="blue"/>
    </visual>
  </link>
  <joint name="right_shoulder_yaw_joint" type="revolute">
    <parent link="right_shoulder_roll_link"/>
    <child link="right_upper_arm_link"/>
    <axis xyz="0 0 1"/>
    <limit lower="-3.0" upper="3.0" effort="60" velocity="10"/>
  </joint>
  <link name="right_elbow_link">
    <visual>
      <origin xyz="0 -0.13 0" rpy="0 0 0"/>
      <geometry>
        <box size="0.06 0.26 0.06"/>
      </geometry>
      <material name="gray"/>
    </visual>
  </link>
  <joint name="right_elbow_joint" type="revolute">
    <origin xyz="0 -0.28 0" rpy="0 0 0"/>
    <parent link="right_upper_arm_link"/>
    <child link="right_elbow_link"/>
    <axis xyz="0 1 0"/>
    <limit lower="-2.5" upper="2.5" effort="60" velocity="10"/>
  </joint>
  <link name="right_wrist_roll_link"/>
  <joint name="right_wrist_roll_joint" type="revolute">
    <origin xyz="0 -0.26 0" rpy="0 0 0"/>
    <parent link="right_elbow_link"/>
    <child link="right_wrist_roll_link"/>
    <axis xyz="1 0 0"/>
    <limit lower="-3.0" upper="3.0" effort="30" velocity="10"/>
  </joint>
  <link name="right_wrist_pitch_link"/>
  <joint name="right_wrist_pitch_joint" type="revolute">
    <parent link="right_wrist_roll_link"/>
    <child link="right_wrist_pitch_link"/>
    <axis xyz="0 1 0"/>
    <limit lower="-2.0" upper="2.0" effort="30" velocity="10"/>
  </joint>
  <link name="right_hand_link">
    <visual>
      <origin xyz="0 -0.06 0" rpy="0 0 0"/>
      <geometry>
        <box size="0.08 0.12 0.04"/>
      </geometry>
      <material name="dark"/>
    </visual>
  </link>
  <joint name="right_wrist_yaw_joint" type="revolute">
    <parent link="right_wrist_pitch_link"/>
    <child link="right_hand_link"/>
    <axis xyz="0 0 1"/>
    <limit lower="-3.0" upper="3.0" effort="30" velocity="10"/>
  </joint>
</robot>
